Workbook

Sheet DATASET
A1: product_id | B1: Product | C1: category | D1: product type | E1: actual_price | F1: discounted_price | G1: expected revenue | H1: actual revenue | I1: discount given | J1: profit/loss | K1: discount_percentage | L1: rating | M1: rating_count | N1: User | O1: no. of users | P1: Image link | Q1: productlink
A2: B07JW9H4J1 | B2: Wayona Nylon Braided USB | C2: Cables&Accessories | D2: Cables | E2: 1099 | F2: 399 | G2: =E2*O2 -> 4396 | H2: =F2*O2 -> 1596 | I2: =(E2*K2)*O2 -> 2813.44 | J2: =H2-G2 -> -2800 | K2: 0.64 | L2: 4.2 | M2: 24269 | N2: Manav,Adarsh gupta,Sundeep,S.Sayeed | O2: =LEN(N2)-LEN(SUBSTITUTE(N2,",",""))+1 -> 4 | P2: =HYPERLINK(#REF!,"Link") -> #REF! | Q2: =HYPERLINK(#REF!,"Link") -> #REF!
A3: B098NS6PVG | B3: Ambrane Unbreakable 60W / | C3: NetworkAdapters | D3: WirelessUSBAdapters | E3: 349 | F3: 199 | G3: =E3*O3 -> 1047 | H3: =F3*O3 -> 597 | I3: =(E3*K3)*O3 -> 450.21 | J3: =H3-G3 -> -450 | K3: 0.43 | L3: 4 | M3: 43994 | N3: ArdKn,Nirbhay kumar,Sagar | O3: =LEN(N3)-LEN(SUBSTITUTE(N3,",",""))+1 -> 3 | P3: =HYPERLINK(#REF!,"Link") -> #REF! | Q3: =HYPERLINK(#REF!,"Link") -> #REF!
A4: B096MSW6CT | B4: Sounce Fast Phone Charging | C4: Accessories | D4: Cables | E4: 1899 | F4: 199 | G4: =E4*O4 -> 9495 | H4: =F4*O4 -> 995 | I4: =(E4*K4)*O4 -> 8545.5 | J4: =H4-G4 -> -8500 | K4: 0.9 | L4: 3.9 | M4: 7928 | N4: Kunal,Himanshu,viswanath,sai niharka,saqib | O4: =LEN(N4)-LEN(SUBSTITUTE(N4,",",""))+1 -> 5 | P4: =HYPERLINK(#REF!,"Link") -> #REF! | Q4: =HYPERLINK(#REF!,"Link") -> #REF!
A5: B08HDJ86NZ | B5: boAt Deuce USB 300 | C5: Televisions | D5: SmartTelevisions | E5: 699 | F5: 329 | G5: =E5*O5 -> 2796 | H5: =F5*O5 -> 1316 | I5: =(E5*K5)*O5 -> 1481.88 | J5: =H5-G5 -> -1480 | K5: 0.53 | L5: 4.2 | M5: 94363 | N5: Omkar dhale,JD,HEMALATHA,Ajwadh | O5: =LEN(N5)-LEN(SUBSTITUTE(N5,",",""))+1 -> 4 | P5: =HYPERLINK(#REF!,"Link") -> #REF! | Q5: =HYPERLINK(#REF!,"Link") -> #REF!
A6: B08CF3B7N1 | B6: Portronics Konnect L 1.2M | C6: Accessories | D6: RemoteControls | E6: 399 | F6: 154 | G6: =E6*O6 -> 1197 | H6: =F6*O6 -> 462 | I6: =(E6*K6)*O6 -> 730.17 | J6: =H6-G6 -> -735 | K6: 0.61 | L6: 4.2 | M6: 16905 | N6: rahuls6099,Swasat Borah,Ajay | O6: =LEN(N6)-LEN(SUBSTITUTE(N6,",",""))+1 -> 3 | P6: =HYPERLINK(#REF!,"Link") -> #REF! | Q6: =HYPERLINK(#REF!,"Link") -> #REF!
A7: B08Y1TFSP6 | B7: pTron Solero TB301 3A | C7: Televisions | D7: StandardTelevisions | E7: 1000 | F7: 149 | G7: =E7*O7 -> 4000 | H7: =F7*O7 -> 596 | I7: =(E7*K7)*O7 -> 3400 | J7: =H7-G7 -> -3404 | K7: 0.85 | L7: 3.9 | M7: 24871 | N7: Jayesh,Rajesh k.,Soopy,amazon | O7: =LEN(N7)-LEN(SUBSTITUTE(N7,",",""))+1 -> 4 | P7: =HYPERLINK(#REF!,"Link") -> #REF! | Q7: =HYPERLINK(#REF!,"Link") -> #REF!
A8: B08WRWPM22 | B8: boAt Micro USB 55 | C8: Accessories | D8: TVMounts,Stands&Turntables | E8: 499 | F8: 176.63 | G8: =E8*O8 -> 998 | H8: =F8*O8 -> 353.26 | I8: =(E8*K8)*O8 -> 648.7 | J8: =H8-G8 -> -644.74 | K8: 0.65 | L8: 4.1 | M8: 15188 | N8: Vivek kumar,Amazon | O8: =LEN(N8)-LEN(SUBSTITUTE(N8,",",""))+1 -> 2 | P8: =HYPERLINK(#REF!,"Link") -> #REF! | Q8: =HYPERLINK(#REF!,"Link") -> #REF!
A9: B08DDRGWTJ | B9: MI Usb Type-C Cable | C9: Accessories | D9: Cables | E9: 299 | F9: 229 | G9: =E9*O9 -> 299 | H9: =F9*O9 -> 229 | I9: =(E9*K9)*O9 -> 68.77 | J9: =H9-G9 -> -70 | K9: 0.23 | L9: 4.3 | M9: 30411 | N9: Pavan A | O9: =LEN(N9)-LEN(SUBSTITUTE(N9,",",""))+1 -> 1 | P9: =HYPERLINK(#REF!,"Link") -> #REF! | Q9: =HYPERLINK(#REF!,"Link") -> #REF!
A10: B008IFXQFU | B10: TP-Link USB WiFi Adapter | C10: Accessories | D10: SpeakerAccessories | E10: 999 | F10: 499 | G10: =E10*O10 -> 1998 | H10: =F10*O10 -> 998 | I10: =(E10*K10)*O10 -> 999 | J10: =H10-G10 -> -1000 | K10: 0.5 | L10: 4.2 | M10: 179691 | N10: Azhar JuMan,Anirudh | O10: =LEN(N10)-LEN(SUBSTITUTE(N10,",",""))+1 -> 2 | P10: =HYPERLINK(#REF!,"Link") -> #REF! | Q10: =HYPERLINK(#REF!,"Link") -> #REF!
A11: B082LZGK39 | B11: Ambrane Unbreakable 60W / | C11: Accessories | D11: Cables | E11: 299 | F11: 199 | G11: =E11*O11 -> 897 | H11: =F11*O11 -> 597 | I11: =(E11*K11)*O11 -> 296.01 | J11: =H11-G11 -> -300 | K11: 0.33 | L11: 4 | M11: 43994 | N11: ArdKn,Nirbhay kumar,Sagar | O11: =LEN(N11)-LEN(SUBSTITUTE(N11,",",""))+1 -> 3 | P11: =HYPERLINK(#REF!,"Link") -> #REF! | Q11: =HYPERLINK(#REF!,"Link") -> #REF!
A12: B08CF3D7QR | B12: Portronics Konnect L POR-1081 | C12: Projectors | E12: 339 | F12: 154 | G12: =E12*O12 -> 1356 | H12: =F12*O12 -> 616 | I12: =(E12*K12)*O12 -> 745.8 | J12: =H12-G12 -> -740 | K12: 0.55 | L12: 4.3 | M12: 13391 | N12: Tanya,Anu,Akshay,Vishal Sagara | O12: =LEN(N12)-LEN(SUBSTITUTE(N12,",",""))+1 -> 4 | P12: =HYPERLINK(#REF!,"Link") -> #REF! | Q12: =HYPERLINK(#REF!,"Link") -> #REF!
A13: B0789LZTCJ | B13: boAt Rugged v3 Extra | C13: Accessories | D13: Adapters | E13: 799 | F13: 299 | G13: =E13*O13 -> 3196 | H13: =F13*O13 -> 1196 | I13: =(E13*K13)*O13 -> 2013.48 | J13: =H13-G13 -> -2000 | K13: 0.63 | L13: 4.2 | M13: 94363 | N13: Omkar dhale,JD,HEMALATHA,Ajwadh | O13: =LEN(N13)-LEN(SUBSTITUTE(N13,",",""))+1 -> 4 | P13: =HYPERLINK(#REF!,"Link") -> #REF! | Q13: =HYPERLINK(#REF!,"Link") -> #REF!
A14: B07KSMBL2H | B14: AmazonBasics Flexible Premium HDMI | C14: SatelliteEquipment | D14: SatelliteReceivers | E14: 700 | F14: 219 | G14: =E14*O14 -> 1400 | H14: =F14*O14 -> 438 | I14: =(E14*K14)*O14 -> 966 | J14: =H14-G14 -> -962 | K14: 0.69 | L14: 4.4 | M14: 426973 | N14: Rishav Gossain,Shashank | O14: =LEN(N14)-LEN(SUBSTITUTE(N14,",",""))+1 -> 2 | P14: =HYPERLINK(#REF!,"Link") -> #REF! | Q14: =HYPERLINK(#REF!,"Link") -> #REF!
A15: B085DTN6R2 | B15: Portronics Konnect CL 20W | C15: Cables&Accessories | D15: Cables | E15: 899 | F15: 350 | G15: =E15*O15 -> 5394 | H15: =F15*O15 -> 2100 | I15: =(E15*K15)*O15 -> 3290.34 | J15: =H15-G15 -> -3294 | K15: 0.61 | L15: 4.2 | M15: 2262 | N15: Priya,Mansi,Plaban,Vivek,Taufique Ahmed,Praveen | O15: =LEN(N15)-LEN(SUBSTITUTE(N15,",",""))+1 -> 6 | P15: =HYPERLINK(#REF!,"Link") -> #REF! | Q15: =HYPERLINK(#REF!,"Link") -> #REF!
A16: B09KLVMZ3B | B16: Portronics Konnect L 1.2M | C16: Accessories | D16: Cables | E16: 399 | F16: 159 | G16: =E16*O16 -> 798 | H16: =F16*O16 -> 318 | I16: =(E16*K16)*O16 -> 478.8 | J16: =H16-G16 -> -480 | K16: 0.6 | L16: 4.1 | M16: 4768 | N16: Deepaak Singh,siva | O16: =LEN(N16)-LEN(SUBSTITUTE(N16,",",""))+1 -> 2 | P16: =HYPERLINK(#REF!,"Link") -> #REF! | Q16: =HYPERLINK(#REF!,"Link") -> #REF!
A17: B083342NKJ | B17: MI Braided USB Type-C | C17: MediaStreamingDevices | D17: StreamingClients | E17: 399 | F17: 349 | G17: =E17*O17 -> 399 | H17: =F17*O17 -> 349 | I17: =(E17*K17)*O17 -> 51.87 | J17: =H17-G17 -> -50 | K17: 0.13 | L17: 4.4 | M17: 18757 | N17: Birendra ku | O17: =LEN(N17)-LEN(SUBSTITUTE(N17,",",""))+1 -> 1 | P17: =HYPERLINK(#REF!,"Link") -> #REF! | Q17: =HYPERLINK(#REF!,"Link") -> #REF!
A18: B0B6F7LX4C | B18: MI 80 cm | C18: AVReceivers&Amplifiers | E18: 24999 | F18: 13999 | G18: =E18*O18 -> 49998 | H18: =F18*O18 -> 27998 | I18: =(E18*K18)*O18 -> 21999.12 | J18: =H18-G18 -> -22000 | K18: 0.44 | L18: 4.2 | M18: 32840 | N18: Manoj maddheshiya,Manoj | O18: =LEN(N18)-LEN(SUBSTITUTE(N18,",",""))+1 -> 2 | P18: =HYPERLINK(#REF!,"Link") -> #REF! | Q18: =HYPERLINK(#REF!,"Link") -> #REF!
A19: B082LSVT4B | B19: Ambrane Unbreakable 60W / | C19: Speakers | D19: TowerSpeakers | E19: 399 | F19: 249 | G19: =E19*O19 -> 1197 | H19: =F19*O19 -> 747 | I19: =(E19*K19)*O19 -> 454.86 | J19: =H19-G19 -> -450 | K19: 0.38 | L19: 4 | M19: 43994 | N19: ArdKn,Nirbhay kumar,Sagar | O19: =LEN(N19)-LEN(SUBSTITUTE(N19,",",""))+1 -> 3 | P19: =HYPERLINK(#REF!,"Link") -> #REF! | Q19: =HYPERLINK(#REF!,"Link") -> #REF!
A20: B08WRBG3XW | B20: boAt Type C A325 | C20: Accessories | D20: 3DGlasses | E20: 499 | F20: 199 | G20: =E20*O20 -> 998 | H20: =F20*O20 -> 398 | I20: =(E20*K20)*O20 -> 598.8 | J20: =H20-G20 -> -600 | K20: 0.6 | L20: 4.1 | M20: 13045 | N20: Rohan Narkar,JAGWINDER | O20: =LEN(N20)-LEN(SUBSTITUTE(N20,",",""))+1 -> 2 | P20: =HYPERLINK(#REF!,"Link") -> #REF! | Q20: =HYPERLINK(#REF!,"Link") -> #REF!
A21: B08DPLCM6T | B21: LG 80 cm | C21: SmartWatches | E21: 21990 | F21: 13490 | G21: =E21*O21 -> 65970 | H21: =F21*O21 -> 40470 | I21: =(E21*K21)*O21 -> 25728.3 | J21: =H21-G21 -> -25500 | K21: 0.39 | L21: 4.3 | M21: 11976 | N21: NIRMAL.N,Manoj kumar,SOMNATH | O21: =LEN(N21)-LEN(SUBSTITUTE(N21,",",""))+1 -> 3 | P21: =HYPERLINK(#REF!,"Link") -> #REF! | Q21: =HYPERLINK(#REF!,"Link") -> #REF!
A22: B09C6HXFC1 | B22: Duracell USB Lightning Apple | C22: MobileAccessories | D22: Chargers | E22: 1799 | F22: 970 | G22: =E22*O22 -> 3598 | H22: =F22*O22 -> 1940 | I22: =(E22*K22)*O22 -> 1655.08 | J22: =H22-G22 -> -1658 | K22: 0.46 | L22: 4.5 | M22: 815 | N22: Prasannavijayaraghavan G.,Preet | O22: =LEN(N22)-LEN(SUBSTITUTE(N22,",",""))+1 -> 2 | P22: =HYPERLINK(#REF!,"Link") -> #REF! | Q22: =HYPERLINK(#REF!,"Link") -> #REF!
A23: B085194JFL | B23: tizum HDMI to VGA | C23: Smartphones&BasicMobiles | D23: Smartphones | E23: 499 | F23: 279 | G23: =E23*O23 -> 1497 | H23: =F23*O23 -> 837 | I23: =(E23*K23)*O23 -> 658.68 | J23: =H23-G23 -> -660 | K23: 0.44 | L23: 3.7 | M23: 10962 | N23: aditya d.,Paranthaman,ashik | O23: =LEN(N23)-LEN(SUBSTITUTE(N23,",",""))+1 -> 3 | P23: =HYPERLINK(#REF!,"Link") -> #REF! | Q23: =HYPERLINK(#REF!,"Link") -> #REF!
A24: B09F6S8BT6 | B24: Samsung 80 cm | C24: MemoryCards | D24: MicroSD | E24: 22900 | F24: 13490 | G24: =E24*O24 -> 45800 | H24: =F24*O24 -> 26980 | I24: =(E24*K24)*O24 -> 18778 | J24: =H24-G24 -> -18820 | K24: 0.41 | L24: 4.3 | M24: 16299 | N24: Rahman Ali,MARIYA | O24: =LEN(N24)-LEN(SUBSTITUTE(N24,",",""))+1 -> 2 | P24: =HYPERLINK(#REF!,"Link") -> #REF! | Q24: =HYPERLINK(#REF!,"Link") -> #REF!
A25: B09NHVCHS9 | B25: Flix Micro Usb Cable | C25: Smartphones&BasicMobiles | D25: BasicMobiles | E25: 199 | F25: 59 | G25: =E25*O25 -> 597 | H25: =F25*O25 -> 177 | I25: =(E25*K25)*O25 -> 417.9 | J25: =H25-G25 -> -420 | K25: 0.7 | L25: 4 | M25: 9378 | N25: $@|\|TO$|-|,Sethu madhav,Akash | O25: =LEN(N25)-LEN(SUBSTITUTE(N25,",",""))+1 -> 3 | P25: =HYPERLINK(#REF!,"Link") -> #REF! | Q25: =HYPERLINK(#REF!,"Link") -> #REF!
A26: B0B1YVCJ2Y | B26: Acer 80 cm | C26: Headphones | D26: In-Ear | E26: 19990 | F26: 11499 | G26: =E26*O26 -> 99950 | H26: =F26*O26 -> 57495 | I26: =(E26*K26)*O26 -> 41979 | J26: =H26-G26 -> -42455 | K26: 0.42 | L26: 4.3 | M26: 4703 | N26: Ayush,ROHIT A.,Kedar,Haran,Santosh | O26: =LEN(N26)-LEN(SUBSTITUTE(N26,",",""))+1 -> 5 | P26: =HYPERLINK(#REF!,"Link") -> #REF! | Q26: =HYPERLINK(#REF!,"Link") -> #REF!
A27: B01M4GGIVU | B27: Tizum High Speed HDMI | C27: MobileAccessories | D27: Chargers | E27: 699 | F27: 199 | G27: =E27*O27 -> 2097 | H27: =F27*O27 -> 597 | I27: =(E27*K27)*O27 -> 1509.84 | J27: =H27-G27 -> -1500 | K27: 0.72 | L27: 4.2 | M27: 12153 | N27: Yashpreet Singh,Abiram,Aakaash | O27: =LEN(N27)-LEN(SUBSTITUTE(N27,",",""))+1 -> 3 | P27: =HYPERLINK(#REF!,"Link") -> #REF! | Q27: =HYPERLINK(#REF!,"Link") -> #REF!
A28: B08B42LWKN | B28: OnePlus 80 cm | C28: MobileAccessories | D28: AutomobileAccessories | E28: 19999 | F28: 14999 | G28: =E28*O28 -> 39998 | H28: =F28*O28 -> 29998 | I28: =(E28*K28)*O28 -> 9999.5 | J28: =H28-G28 -> -10000 | K28: 0.25 | L28: 4.2 | M28: 34899 | N28: ATHARVA BONDRE,Sujitkumar | O28: =LEN(N28)-LEN(SUBSTITUTE(N28,",",""))+1 -> 2 | P28: =HYPERLINK(#REF!,"Link") -> #REF! | Q28: =HYPERLINK(#REF!,"Link") -> #REF!
A29: B094JNXNPV | B29: Ambrane Unbreakable 3 in | C29: MobileAccessories | D29: Chargers | E29: 399 | F29: 299 | G29: =E29*O29 -> 1596 | H29: =F29*O29 -> 1196 | I29: =(E29*K29)*O29 -> 399 | J29: =H29-G29 -> -400 | K29: 0.25 | L29: 4 | M29: 2766 | N29: Anand sarma,lokeshnist,C,SAI | O29: =LEN(N29)-LEN(SUBSTITUTE(N29,",",""))+1 -> 4 | P29: =HYPERLINK(#REF!,"Link") -> #REF! | Q29: =HYPERLINK(#REF!,"Link") -> #REF!
A30: B09W5XR9RT | B30: Duracell USB C To | C30: MobileAccessories | D30: Cables&Adapters | E30: 1999 | F30: 970 | G30: =E30*O30 -> 3998 | H30: =F30*O30 -> 1940 | I30: =(E30*K30)*O30 -> 2038.98 | J30: =H30-G30 -> -2058 | K30: 0.51 | L30: 4.4 | M30: 184 | N30: Amazon Customer,Govind | O30: =LEN(N30)-LEN(SUBSTITUTE(N30,",",""))+1 -> 2 | P30: =HYPERLINK(#REF!,"Link") -> #REF! | Q30: =HYPERLINK(#REF!,"Link") -> #REF!
A31: B077Z65HSD | B31: boAt A400 USB Type-C | C31: MobileAccessories | D31: Photo&VideoAccessories | E31: 999 | F31: 299 | G31: =E31*O31 -> 2997 | H31: =F31*O31 -> 897 | I31: =(E31*K31)*O31 -> 2097.9 | J31: =H31-G31 -> -2100 | K31: 0.7 | L31: 4.3 | M31: 20850 | N31: GHOST,Amazon Customer,A | O31: =LEN(N31)-LEN(SUBSTITUTE(N31,",",""))+1 -> 3 | P31: =HYPERLINK(#REF!,"Link") -> #REF! | Q31: =HYPERLINK(#REF!,"Link") -> #REF!
A32: B00NH11PEY | B32: AmazonBasics USB 2.0 - | C32: MobileAccessories | D32: Photo&VideoAccessories | E32: 750 | F32: 199 | G32: =E32*O32 -> 6000 | H32: =F32*O32 -> 1592 | I32: =(E32*K32)*O32 -> 4380 | J32: =H32-G32 -> -4408 | K32: 0.73 | L32: 4.5 | M32: 74976 | N32: Pravin Kumar,Maestrov,rag,Mukundha2good,Amazon_Shopper,Sonic,Pratap,Amazon | O32: =LEN(N32)-LEN(SUBSTITUTE(N32,",",""))+1 -> 8 | P32: =HYPERLINK(#REF!,"Link") -> #REF! | Q32: =HYPERLINK(#REF!,"Link") -> #REF!
A33: B09CMM3VGK | B33: Ambrane 60W / 3A | C33: MobileAccessories | D33: Stands | E33: 499 | F33: 179 | G33: =E33*O33 -> 1497 | H33: =F33*O33 -> 537 | I33: =(E33*K33)*O33 -> 958.08 | J33: =H33-G33 -> -960 | K33: 0.64 | L33: 4 | M33: 1934 | N33: Rishabh,Amazon Customer,Darpan | O33: =LEN(N33)-LEN(SUBSTITUTE(N33,",",""))+1 -> 3 | P33: =HYPERLINK(#REF!,"Link") -> #REF! | Q33: =HYPERLINK(#REF!,"Link") -> #REF!
... A42: B00NH11KIK | B42: AmazonBasics USB 2.0 Cable | C42: LaptopAccessories | D42: CameraPrivacyCovers | E42: 695 | F42: 209 | G42: =E42*O42 -> 4865 | H42: =F42*O42 -> 1463 | I42: =(E42*K42)*O42 -> 3405.5 | J42: =H42-G42 -> -3402 | K42: 0.7 | L42: 4.5 | M42: 107687 | N42: Shiva,Uzef,kottala samuel,Renjith,Dhivakaran,Mark,Utkarsh | O42: =LEN(N42)-LEN(SUBSTITUTE(N42,",",""))+1 -> 7 | P42: =HYPERLINK(#REF!,"Link") -> #REF! | Q42: =HYPERLINK(#REF!,"Link") -> #REF!
A43: B09JPC82QC | B43: Mi 108 cm | C43: Adapters | E43: 34999 | F43: 19999 | G43: =E43*O43 -> 104997 | H43: =F43*O43 -> 59997 | I43: =(E43*K43)*O43 -> 45148.71 | J43: =H43-G43 -> -45000 | K43: 0.43 | L43: 4.3 | M43: 27151 | N43: Sameer Patil,TechnoLoon,Deepti | O43: =LEN(N43)-LEN(SUBSTITUTE(N43,",",""))+1 -> 3 | P43: =HYPERLINK(#REF!,"Link") -> #REF! | Q43: =HYPERLINK(#REF!,"Link") -> #REF!
A44: B07JW1Y6XV | B44: Wayona Nylon Braided 3A | C44: MobileAccessories | D44: DÃ©cor | E44: 1099 | F44: 399 | G44: =E44*O44 -> 4396 | H44: =F44*O44 -> 1596 | I44: =(E44*K44)*O44 -> 2813.44 | J44: =H44-G44 -> -2800 | K44: 0.64 | L44: 4.2 | M44: 24269 | N44: Manav,Adarsh gupta,Sundeep,S.Sayeed | O44: =LEN(N44)-LEN(SUBSTITUTE(N44,",",""))+1 -> 4 | P44: =HYPERLINK(#REF!,"Link") -> #REF! | Q44: =HYPERLINK(#REF!,"Link") -> #REF!
A45: B07KRCW6LZ | B45: TP-Link Nano AC600 USB | C45: MobileAccessories | D45: Mounts | E45: 1599 | F45: 999 | G45: =E45*O45 -> 3198 | H45: =F45*O45 -> 1998 | I45: =(E45*K45)*O45 -> 1215.24 | J45: =H45-G45 -> -1200 | K45: 0.38 | L45: 4.3 | M45: 12093 | N45: Paul Joe,Simon | O45: =LEN(N45)-LEN(SUBSTITUTE(N45,",",""))+1 -> 2 | P45: =HYPERLINK(#REF!,"Link") -> #REF! | Q45: =HYPERLINK(#REF!,"Link") -> #REF!
A46: B09NJN8L25 | B46: FLiX | C46: PenDrives | E46: 199 | F46: 59 | G46: =E46*O46 -> 597 | H46: =F46*O46 -> 177 | I46: =(E46*K46)*O46 -> 417.9 | J46: =H46-G46 -> -420 | K46: 0.7 | L46: 4 | M46: 9378 | N46: $@|\|TO$|-|,Sethu madhav,Akash | O46: =LEN(N46)-LEN(SUBSTITUTE(N46,",",""))+1 -> 3 | P46: =HYPERLINK(#REF!,"Link") -> #REF! | Q46: =HYPERLINK(#REF!,"Link") -> #REF!
A47: B07XJYYH7L | B47: Wecool Nylon Braided Multifunction | C47: Keyboards,Mice&InputDevices | D47: Mice | E47: 999 | F47: 333 | G47: =E47*O47 -> 3996 | H47: =F47*O47 -> 1332 | I47: =(E47*K47)*O47 -> 2677.32 | J47: =H47-G47 -> -2664 | K47: 0.67 | L47: 3.3 | M47: 9792 | N47: Amazon Customer,DHONDU,Saurabh,Promod | O47: =LEN(N47)-LEN(SUBSTITUTE(N47,",",""))+1 -> 4 | P47: =HYPERLINK(#REF!,"Link") -> #REF! | Q47: =HYPERLINK(#REF!,"Link") -> #REF!
A48: B002PD61Y4 | B48: D-Link DWA-131 300 Mbps | C48: Keyboards,Mice&InputDevices | D48: GraphicTablets | E48: 1208 | F48: 507 | G48: =E48*O48 -> 4832 | H48: =F48*O48 -> 2028 | I48: =(E48*K48)*O48 -> 2802.56 | J48: =H48-G48 -> -2804 | K48: 0.58 | L48: 4.1 | M48: 8131 | N48: nilesh,EAGLE,Manoj KNS,Titus | O48: =LEN(N48)-LEN(SUBSTITUTE(N48,",",""))+1 -> 4 | P48: =HYPERLINK(#REF!,"Link") -> #REF! | Q48: =HYPERLINK(#REF!,"Link") -> #REF!
...

Sheet DASHBOARD
G1: CATEGORY WISE AVG DISCOUNT PERCENTAGE | T1: CATEGORY WISE RATING
AK11: COUNT OF CATEGOTY
I19: AVG PRICE OF EACH CATEGORY
T21: AVG PRICE AND AVG RATING

Sheet ANALYSIS
C1: ANALYSIS
A2: total product | H2: LIMITATIONS
A3: 1466 | C3: AVERAGE SELLING PRICE | E3: =AVERAGE(DATASET!F:F) -> 3125.3109
C4: Total Products | E4: 1466 | H4: The dataset does not include Units Sold.
H5: Brand information is limited.
C6: Avg Discount % | E6: =AVERAGE(DATASET!K:K) -> 0.47691468 | H6: Revenue and Profit cannot be calculated accurately.
C7: Avg Rating | E7: =AVERAGE(DATASET!L:L) -> 4.0965847 | H7: Estimated Revenue Potential is based on Rating Count.
C8: Total Reviews | E8: =SUM(DATASET!M:M) -> 26766377 | H8: Analysis focuses on product performance rather than actual financial performance.
C9: HIGHEST REVIEW | E9: =K18 -> 426973
C10: PRODUCT | E10: =L18 -> AmazonBasics Flexible Premium HDMI
B12: expected revenue | C12: actual revenue | D12: gross margin
B13: =SUM(DATASET!G:G) -> 22879163 | C13: =SUM(DATASET!H:H) -> 13062023 | D13: =C13-B13 -> -9817140.1 | J13: CORRELATION BETWWEN REVIEW COUNT AND RATINGS
D14: =(D13)/B13*100 -> -42.90865 | J14: =CORREL(DATASET!M:M,DATASET!L:L) -> 0.10223482
B17: correlation between discount and price of product | F17: trigger | G17: value | H17: product | J17: review | L17: PRODUCT
B18: =CORREL(DATASET!K:K,DATASET!L:L) -> -0.15537544 | F18: max price | G18: =MAX(DATASET!F:F) -> 77990 | H18: =_xlfn.XLOOKUP(G18,DATASET!$F:$F,DATASET!$B:$B) -> Sony Bravia 164 cm | J18: max | K18: =MAX(DATASET!M:M) -> 426973 | L18: =_xlfn.XLOOKUP(ANALYSIS!K18,DATASET!M:M,DATASET!B:B,) -> AmazonBasics Flexible Premium HDMI | M18: =_xlfn.XLOOKUP(K18,DATASET!M:M,DATASET!L:L) -> 4.4
F19: min price | G19: =MIN(DATASET!F:F) -> 39 | H19: =_xlfn.XLOOKUP(G19,DATASET!$F:$F,DATASET!$B:$B) -> GIZGA essentials Universal Silicone | J19: min | K19: =MIN(DATASET!M:M) -> 2 | L19: =_xlfn.XLOOKUP(ANALYSIS!K19,DATASET!M:M,DATASET!B:B,) -> Khaitan ORFin Fan heater | M19: =_xlfn.XLOOKUP(K19,DATASET!M:M,DATASET!L:L) -> 2
B20: correlation between discounting rate and profit nad loss | F20: max rating | G20: =MAX(DATASET!L:L) -> 5
B21: =CORREL(DATASET!I:I,DATASET!J:J) -> -0.9999761 | F21: min rating | G21: =MIN(DATASET!L:L) -> 2
B23: =CORREL(DATASET!M:M,DATASET!L:L) -> 0.10223482

Sheet Sheet6
A4: Row Labels | B4: Count of Product | E4: Average Price by Category (Column Chart)
A5: Accessories | B5: 123 | E5: Average Discount by Category (Bar Chart)
A6: Adapters | B6: 15 | E6: Rating Distribution (Histogram/Column)
A7: Adapters&Multi-Outlets | B7: 7 | E7: Price vs Rating (Scatter Plot)
A8: AirConditioners | B8: 7 | E8: Top 10 Most Reviewed Products (Bar Chart)
A9: AirPurifiers | B9: 7 | E9: Product Count by Category (Pie or Doughnut Chart)
A10: Audio&VideoAccessories | B10: 28
A11: AVReceivers&Amplifiers | B11: 8
A12: Cables&Accessories | B12: 38
A13: Calculators | B13: 22
A14: Cases | B14: 7
A15: Coffee,Tea&Espresso | B15: 49
A16: Condenser | B16: 8
A17: CordManagement | B17: 7
A18: DataCards&Dongles | B18: 7
A19: DisposableBatteries | B19: 8
A20: Drawing&PaintingSupplies | B20: 7
A21: DrawingMaterials | B21: 14
... A77: Grand Total | B77: 1465

Sheet Sheet1
A2: Row Labels | B2: Average of actual_price | C2: Average of discounted_price | D2: Average of discount_percentage | E2: Average of rating
A3: Row Labels | B3: Count of Product | C3: Count of product type
A4: AVReceivers&Amplifiers | B4: 8
A5: Grand Total | B5: 8

Sheet Sheet12
A1: Row Labels | B1: Average of discounted_price | C1: Average of rating
A2: Accessories | B2: 4271.1644 | C2: 4.0875
A3: Adapters | B3: 10089 | C3: 4.15
A4: Adapters&Multi-Outlets | B4: 849 | C4: 4.3
A5: AirConditioners | B5: 8990 | C5: 3.9
A6: AirPurifiers | B6: 1399 | C6: 4.4
A7: Audio&VideoAccessories | B7: 7961 | C7: 4.1
A8: AVReceivers&Amplifiers | B8: 13999 | C8: 4.2
A9: Cables&Accessories | B9: 5307.2 | C9: 4.28
A10: Calculators | B10: 10192 | C10: 4.2333333
A11: Cases | B11: 18990 | C11: 4.2
A12: Coffee,Tea&Espresso | B12: 7242 | C12: 4.0571429
A13: Condenser | B13: 1199 | C13: 4.4
... A72: WaterPurifiers&Accessories | B72: 11245.667 | C72: 4.1666667
B73: 2955.2613 | C73: 4.0908589
C74: 4.0965847

Sheet Sheet5
A1: Row Labels | B1: Average of discount_percentage
A2: AVReceivers&Amplifiers | B2: 0.47
A3: Grand Total | B3: 0.47
F44: Row Labels | G44: Average of rating
F45: Accessories | G45: 4.1227642
F46: Adapters | G46: 3.9333333
F47: Adapters&Multi-Outlets | G47: 4.1428571
F48: AirConditioners | G48: 3.9714286
F49: AirPurifiers | G49: 4.2285714
F50: Audio&VideoAccessories | G50: 4.05
F51: AVReceivers&Amplifiers | G51: 4.0625
F52: Cables&Accessories | G52: 4.1026316
F53: Calculators | G53: 4.1428571
F54: Cases | G54: 4.0142857
F55: Coffee,Tea&Espresso | G55: 4.1326531
F56: Condenser | G56: 4.15
... F117: Grand Total | G117: 4.0965847

Sheet Sheet10
A1: Row Labels | B1: Average of discounted_price
A2: Accessories | B2: 2817.6446
A3: Adapters | B3: 2594.8
A4: Adapters&Multi-Outlets | B4: 3210.7143
A5: AirConditioners | B5: 5144.8571
A6: AirPurifiers | B6: 6257.2857
A7: Audio&VideoAccessories | B7: 4313.6071
A8: AVReceivers&Amplifiers | B8: 4222.625
A9: Cables&Accessories | B9: 3509.2105
A10: Calculators | B10: 5901.1364
A11: Cases | B11: 4237.1429
A12: Coffee,Tea&Espresso | B12: 2213.5918
A13: Condenser | B13: 11555.5
... A74: Grand Total | B74: 3125.3109

Sheet Sheet11
A1: Row Labels | B1: Average of discounted_price | C1: Average of rating
A2: Accessories | B2: 2817.6446 | C2: 4.1227642
A3: Adapters | B3: 2594.8 | C3: 3.9333333
A4: Adapters&Multi-Outlets | B4: 3210.7143 | C4: 4.1428571
A5: AirConditioners | B5: 5144.8571 | C5: 3.9714286
A6: AirPurifiers | B6: 6257.2857 | C6: 4.2285714
A7: Audio&VideoAccessories | B7: 4313.6071 | C7: 4.05
A8: AVReceivers&Amplifiers | B8: 4222.625 | C8: 4.0625
A9: Cables&Accessories | B9: 3509.2105 | C9: 4.1026316
A10: Calculators | B10: 5901.1364 | C10: 4.1428571
A11: Cases | B11: 4237.1429 | C11: 4.0142857
A12: Coffee,Tea&Espresso | B12: 2213.5918 | C12: 4.1326531
A13: Condenser | B13: 11555.5 | C13: 4.15
... A74: Grand Total | B74: 3125.3109 | C74: 4.0965847

Sheet Sheet14
A1: Row Labels | B1: Average of discount_percentage
A2: Accessories | B2: 0.47804878
A3: Adapters | B3: 0.46933333
A4: Adapters&Multi-Outlets | B4: 0.44571429
A5: AirConditioners | B5: 0.38
A6: AirPurifiers | B6: 0.40714286
A7: Audio&VideoAccessories | B7: 0.49
A8: AVReceivers&Amplifiers | B8: 0.47
A9: Cables&Accessories | B9: 0.47315789
A10: Calculators | B10: 0.46727273
A11: Cases | B11: 0.51428571
A12: Coffee,Tea&Espresso | B12: 0.50530612
A13: Condenser | B13: 0.49625
... A74: Grand Total | B74: 0.47691468
